Workbook
Name Company_Name: DCF!$D$8
Name Company_Name: DCF!$D$8
Name Cost_of_Debt: WACC!$F$8
Name Cost_of_Preferred: WACC!$F$9
Name Diluted_Shares: DCF!$I$32
Name Discount_Rate: DCF!$D$12
Name Equity_Risk_Premium: WACC!$F$7
Name Hist_Year: DCF!$D$14
Name Hist_Year: DCF!$D$13
Name Hist_Year: DCF!$D$14
Name Risk_Free_Rate: WACC!$F$6
Name Share_Price: DCF!$D$10
Name Share_Price: DCF!$D$13
Name Tax_Rate: DCF!$D$13
Name Tax_Rate: DCF!$D$13
Name Terminal_Growth_Rate: DCF!#REF!
Name Terminal_Multiple: DCF!#REF!
Name Ticker: DCF!$D$9
Name WACC: WACC!$L$41

Sheet DCF
B2: =Company_Name&" - Discounted Cash Flow Analysis" -> Best Buy Co. - Discounted Cash Flow Analysis
B3: ($ in Millions Except Per Share and Per Unit Data)
B6: DCF Assumptions & Output:
C8: Company Name: | D8: Best Buy Co. | F8: Terminal Value - Multiples Method: | K8: Terminal Value - Perpetuity Growth Method:
C9: Ticker: | D9: BBY
C10: Current Share Price: | D10: 74.29 | F10: Median TEV / EBITDA of Comps: | I10: ='Public-Comps'!AF15 -> 10.781943 | K10: Expected Long-Term GDP Growth: | N10: 0.015
F11: Baseline Terminal EBITDA Multiple: | I11: 7.5 | K11: Baseline Terminal FCF Growth Rate: | N11: 0.005
C12: Discount Rate (WACC): | D12: =WACC -> 0.077012802
C13: Effective Tax Rate: | D13: 0.21 | F13: Baseline Terminal Value: | I13: =I11*Q95 -> 21045.232 | K13: Baseline Terminal Value: | N13: =Q89*(1+N11)/(Discount_Rate-N11) -> 27896.829
C14: Last Fiscal Year: | D14: 45689 | F14: Implied Terminal FCF Growth Rate: | I14: =(I13*Discount_Rate-Q89)/(I13+Q89) -> -0.016411179 | K14: Implied Terminal EBITDA Multiple: | N14: =N13/Q95 -> 9.94174
C16: Current Equity Value: | D16: =+I32*Share_Price -> 16120.93 | F16: (+) PV of Terminal Value: | I16: =I13/((1+Discount_Rate)^$Q$92) -> 10021.784 | K16: =+F16 -> (+) PV of Terminal Value: | N16: =N13/((1+Discount_Rate)^$Q$92) -> 13284.53
C17: (-) Cash & Cash-Equivalents: | D17: -1447 | F17: (+) Sum of PV of Free Cash Flows: | I17: =SUM($H$93:$Q$93) -> 13363.924 | K17: =+F17 -> (+) Sum of PV of Free Cash Flows: | N17: =SUM($H$93:$Q$93) -> 13363.924
C18: (-) Equity Investments: | D18: 0 | F18: Implied Enterprise Value: | I18: =SUM(I16:I17) -> 23385.709 | K18: =+F18 -> Implied Enterprise Value: | N18: =SUM(N16:N17) -> 26648.454
C19: (-) Other Non-Core Assets, Net: | D19: 0
C20: (-) Net Operating Losses: | D20: -25.1 | F20: % of Implied TEV from Terminal Value: | I20: =+I16/I18 -> 0.42854311 | K20: =+F20 -> % of Implied TEV from Terminal Value: | N20: =+N16/N18 -> 0.49851034
C21: (+) Total Debt & Finance Leases: | D21: =4070 -> 4070
C22: (+) Preferred Stock: | D22: 0 | F22: (+) Cash & Cash-Equivalents: | I22: =-D17 -> 1447 | K22: (+) Cash & Cash-Equivalents: | N22: =+I22 -> 1447
C23: (+) Noncontrolling Interests: | D23: 0 | F23: (+) Equity Investments: | I23: =-D18 -> 0 | K23: (+) Equity Investments: | N23: =+I23 -> 0
C24: (+) Unfunded Pension Obligations: | D24: 0 | F24: (+) Other Non-Core Assets, Net: | I24: =-D19 -> 0 | K24: (+) Other Non-Core Assets, Net: | N24: =+I24 -> 0
C25: Current Enterprise Value: | D25: =SUM(D16:D24) -> 18718.83 | F25: (+) Net Operating Losses: | I25: =-D20 -> 25.1 | K25: (+) Net Operating Losses: | N25: =+I25 -> 25.1
F26: (-) Total Debt & Capital Leases: | I26: =-D21 -> -4070 | K26: (-) Total Debt: | N26: =+I26 -> -4070
F27: (-) Preferred Stock: | I27: =-D22 -> 0 | K27: (-) Preferred Stock: | N27: =+I27 -> 0
F28: (-) Noncontrolling Interests: | I28: =-D23 -> 0 | K28: (-) Noncontrolling Interests: | N28: =+I28 -> 0
F29: (-) Unfunded Pension Obligations: | I29: =-D24 -> 0 | K29: (-) Unfunded Pension Obligations: | N29: =+I29 -> 0
F30: Implied Equity Value: | I30: =I18+SUM(I22:I29) -> 20787.809 | K30: Implied Equity Value: | N30: =N18+SUM(N22:N29) -> 24050.554
F32: Diluted Shares Outstanding: | I32: 217 | K32: Diluted Shares Outstanding: | N32: =I32 -> 217
F34: Implied Share Price from DCF: | I34: =+I30/I32 -> 95.796353 | K34: Implied Share Price from DCF: | N34: =+N30/N32 -> 110.83205
F35: Premium / (Discount) to Current: | I35: =+I34/Share_Price-1 -> 0.2894919 | K35: Premium / (Discount) to Current: | N35: =+N34/Share_Price-1 -> 0.49188379
E37: Historical: | H37: Projected:
B38: Unlevered Free Cash Flow Projections: | D38: Units: | E38: =EOMONTH(F38,-12) -> 44985 | F38: =EOMONTH(G38,-12) -> 45351 | G38: =Hist_Year -> 45689 | H38: =EOMONTH(G38,12) -> 46081 | I38: =EOMONTH(H38,12) -> 46446 | J38: =EOMONTH(I38,12) -> 46812 | K38: =EOMONTH(J38,12) -> 47177 | L38: =EOMONTH(K38,12) -> 47542 | M38: =EOMONTH(L38,12) -> 47907 | N38: =EOMONTH(M38,12) -> 48273 | O38: =EOMONTH(N38,12) -> 48638 | ... Q38: =EOMONTH(P38,12) -> 49368 | V38: FCF Build-Up: | AB38: FY25 | AC38: FY26
C40: Retail Square Feet: | D40: M Sq. Ft. | E40: 41 | F40: 40.394 | G40: 40.142 | H40: =G40*(1+H41) -> 40.142 | I40: =H40*(1+I41) -> 40.142 | J40: =I40*(1+J41) -> 40.142 | K40: =J40*(1+K41) -> 39.94129 | L40: =K40*(1+L41) -> 39.741584 | M40: =L40*(1+M41) -> 39.542876 | N40: =M40*(1+N41) -> 39.345161 | O40: =N40*(1+O41) -> 39.148435 | ... Q40: =P40*(1+Q41) -> 38.75793 | V40: Earnings Before Intersets & Taxes (EBIT): | AB40: 1734 | AC40: 1760
C41: Growth Rate: | D41: % | E41: =IFERROR(E40/D40-1,"N/A") -> N/A | F41: =IFERROR(F40/E40-1,"N/A") -> -0.014780488 | G41: =IFERROR(G40/F40-1,"N/A") -> -0.0062385503 | H41: 0 | I41: 0 | J41: 0 | K41: -0.005 | L41: -0.005 | M41: -0.005 | N41: -0.005 | O41: -0.005 | P41: -0.005 | Q41: -0.005 | V41: (-) Taxes on EBIT: | AB41: =-AB40*Tax_Rate -> -364.14 | AC41: =-AC40*Tax_Rate -> -369.6
V42: Net Operating Progit After Taxes (NOPAT): | AB42: =AB40+AB41 -> 1369.86 | AC42: =AC40+AC41 -> 1390.4
C43: Sales per Square Foot: | D43: $ / Sq. Ft. | E43: =E61/E40 -> 1129.2195 | F43: =F61/F40 -> 1075.7043 | G43: =G61/G40 -> 1034.5274 | H43: =G43*(1+H44) -> 1050.0453 | I43: =H43*(1+I44) -> 1065.796 | J43: =I43*(1+J44) -> 1079.6514 | K43: =J43*(1+K44) -> 1093.6868 | L43: =K43*(1+L44) -> 1104.6237 | M43: =L43*(1+M44) -> 1115.6699 | N43: =M43*(1+N44) -> 1126.8266 | O43: =N43*(1+O44) -> 1138.0949 | ... Q43: =P43*(1+Q44) -> 1156.3773 | V43: (+) D&A: | AB43: 866 | AC43: 879
C44: Growth Rate: | D44: % | E44: =IFERROR(E43/D43-1,"N/A") -> N/A | F44: =IFERROR(F43/E43-1,"N/A") -> -0.047391317 | G44: =IFERROR(G43/F43-1,"N/A") -> -0.038279 | H44: 0.015 | I44: 0.015 | J44: 0.013 | K44: 0.013 | L44: 0.01 | M44: 0.01 | N44: 0.01 | O44: 0.01 | P44: 0.008 | Q44: 0.008 | V44: (+/-) Change in Working Capital: | AB44: -259 | AC44: 37
V45: (-) Capital Expenditures: | AB45: -706 | AC45: -720
C46: COGS and OpEx per Square Foot: | D46: $ / Sq. Ft. | E46: =(E61-E66)/E40 -> 1081.8537 | F46: =(F61-F66)/F40 -> 1032.9504 | G46: =(G61-G66)/G40 -> 991.33078 | H46: =G46*(1+H47) -> 1006.2007 | I46: =H46*(1+I47) -> 1021.2937 | J46: =I46*(1+J47) -> 1034.5706 | K46: =J46*(1+K47) -> 1048.02 | L46: =K46*(1+L47) -> 1058.5002 | M46: =L46*(1+M47) -> 1069.0852 | N46: =M46*(1+N47) -> 1079.776 | O46: =N46*(1+O47) -> 1090.5738 | ... Q46: =P46*(1+Q47) -> 1108.0928 | V46: (+/-) Other Operating Activities: | AB46: 148 | AC46: 238
C47: Growth Rate: | D47: % | E47: =IFERROR(E46/D46-1,"N/A") -> N/A | F47: =IFERROR(F46/E46-1,"N/A") -> -0.045203175 | G47: =IFERROR(G46/F46-1,"N/A") -> -0.040292023 | H47: 0.015 | I47: 0.015 | J47: 0.013 | K47: 0.013 | L47: 0.01 | M47: 0.01 | N47: 0.01 | O47: 0.01 | P47: 0.008 | Q47: 0.008 | V47: (+/-) Deferred Taxes: | AB47: 105 | AC47: 89
V48: Unlevered Free Cash Flow (UCF): | AB48: =SUM(AB42:AB47) -> 1523.86 | AC48: =SUM(AC42:AC47) -> 1913.4
C49: Maintenance CapEx per Square Foot: | D49: $ / Sq. Ft. | E49: =-E86/E40 -> 22.682927 | F49: =-F86/F40 -> 19.681141 | G49: =-G86/G40 -> 17.587564 | H49: =G49*(1+H50) -> 17.939315 | I49: =H49*(1+I50) -> 18.298102 | J49: =I49*(1+J50) -> 18.664064 | K49: =J49*(1+K50) -> 19.037345 | L49: =K49*(1+L50) -> 19.322905 | M49: =L49*(1+M50) -> 19.612749 | N49: =M49*(1+N50) -> 19.90694 | O49: =N49*(1+O50) -> 20.205544 | ... Q49: =P49*(1+Q50) -> 20.611676
...

Sheet WACC
B2: ="WACC Analysis - "&TEXT(Company_Name,"") -> WACC Analysis - Best Buy Co.
B3: =[1]DCF!$B$3 -> ($ in Millions Except Per Share and Per Unit Data)
B5: Discount Rate Calculations - Assumptions:
B6: Risk-Free Rate: | F6: 0.042
B7: Equity Risk Premium: | F7: 0.0433
B8: Pre-Tax Cost of Debt: | F8: 0.042
B9: Cost of Preferred Stock: | F9: 0
B11: Comparable Companies - Unlevered Beta Calculation:
D12: Levered | G12: Preferred | I12: Equity | L12: Unlevered
B13: Name | C13: Ticker | D13: Beta | E13: Debt | F13: % Debt | G13: Stock | H13: % Preferred | I13: Value | J13: % Equity | K13: Tax Rate | L13: Beta
B14: ='Public-Comps'!B8 -> The Kroger Co. | C14: ='Public-Comps'!C8 -> KR | D14: 0.58 | E14: 25082 | F14: =+E14/($E14+$G14+$I14) -> 0.34581552 | G14: 0 | H14: =+G14/($E14+$G14+$I14) -> 0 | I14: ='Public-Comps'!F8 -> 47448 | J14: =+I14/($E14+$G14+$I14) -> 0.65418448 | K14: 0.24371157 | L14: =IFERROR(D14/(1+(E14/I14)*(1-K14)+G14/I14),"N/A") -> 0.41434793
B15: ='Public-Comps'!B9 -> Target Corporation | C15: ='Public-Comps'!C9 -> TGT | D15: 1.12 | E15: 11178 | F15: =+E15/($E15+$G15+$I15) -> 0.22180094 | G15: 0 | H15: =+G15/($E15+$G15+$I15) -> 0 | I15: ='Public-Comps'!F9 -> 39218.54 | J15: =+I15/($E15+$G15+$I15) -> 0.77819906 | K15: 0.2895 | L15: =IFERROR(D15/(1+(E15/I15)*(1-K15)+G15/I15),"N/A") -> 0.93138869
B16: ='Public-Comps'!B10 -> BJ’s Wholesale Club Holdings, Inc. | C16: ='Public-Comps'!C10 -> BJ | D16: 0.31 | E16: 2843.916 | F16: =+E16/($E16+$G16+$I16) -> 0.19058626 | G16: 0 | H16: =+G16/($E16+$G16+$I16) -> 0 | I16: ='Public-Comps'!F10 -> 12078.02 | J16: =+I16/($E16+$G16+$I16) -> 0.80941374 | K16: 0.23674912 | L16: =IFERROR(D16/(1+(E16/I16)*(1-K16)+G16/I16),"N/A") -> 0.26277496
B17: ='Public-Comps'!B11 -> The TJX Companies, Inc. | C17: ='Public-Comps'!C11 -> TJX | D17: 0.77 | E17: 12778 | F17: =+E17/($E17+$G17+$I17) -> 0.071729005 | G17: 0 | H17: =+G17/($E17+$G17+$I17) -> 0 | I17: ='Public-Comps'!F11 -> 165364.72 | J17: =+I17/($E17+$G17+$I17) -> 0.928271 | K17: 0.21240534 | L17: =IFERROR(D17/(1+(E17/I17)*(1-K17)+G17/I17),"N/A") -> 0.72582709
B18: ='Public-Comps'!B12 -> Costco Wholesale | C18: ='Public-Comps'!C12 -> COST | D18: 0.98 | E18: 8173 | F18: =+E18/($E18+$G18+$I18) -> 0.17074193 | G18: 0 | H18: =+G18/($E18+$G18+$I18) -> 0 | I18: ='Public-Comps'!F12 -> 39694.562 | J18: =+I18/($E18+$G18+$I18) -> 0.82925807 | K18: 0.24358435 | L18: =IFERROR(D18/(1+(E18/I18)*(1-K18)+G18/I18),"N/A") -> 0.84793873
B19: ='Public-Comps'!B13 -> Lowe's Companies, Inc. | C19: ='Public-Comps'!C13 -> LOW | D19: 0.96 | E19: 39678 | F19: =+E19/($E19+$G19+$I19) -> 0.23531936 | G19: 0 | H19: =+G19/($E19+$G19+$I19) -> 0 | I19: ='Public-Comps'!F13 -> 128935.41 | J19: =+I19/($E19+$G19+$I19) -> 0.76468064 | K19: 0.24358435 | L19: =IFERROR(D19/(1+(E19/I19)*(1-K19)+G19/I19),"N/A") -> 0.77873033
B21: Median: | D21: =MEDIAN(D14:D19) -> 0.865 | E21: =MEDIAN(E14:E19) -> 11978 | F21: =MEDIAN(F14:F19) -> 0.2061936 | G21: =MEDIAN(G14:G19) -> 0 | H21: =MEDIAN(H14:H19) -> 0 | I21: =MEDIAN(I14:I19) -> 43571.281 | J21: =MEDIAN(J14:J19) -> 0.7938064 | K21: =MEDIAN(K14:K19) -> 0.24358435 | L21: =MEDIAN(L14:L19) -> 0.75227871
B23: =Company_Name -> Best Buy Co. | C23: =Ticker -> BBY | D23: 1.39 | E23: 4053 | F23: =+E23/($E23+$G23+$I23) -> 0.20090285 | G23: 0 | H23: 0 | I23: ='Public-Comps'!F21 -> 16120.93 | J23: =+I23/($E23+$G23+$I23) -> 0.79909715 | K23: 0.25 | L23: =IFERROR(D23/(1+(E23/I23)*(1-K23)+G23/I23),"N/A") -> 1.1694832
B25: =TEXT(Company_Name,"")& " - Levered Beta & WACC Calculation:" -> Best Buy Co. - Levered Beta & WACC Calculation:
D26: Unlevered | G26: Preferred | I26: Equity | L26: Levered
C27: Ticker | D27: Beta | E27: Debt | F27: % Debt | G27: Stock | H27: % Preferred | I27: Value | J27: % Equity | K27: Tax Rate | L27: Beta
B28: Current Capital Structure: | C28: =Ticker -> BBY | D28: =+L21 -> 0.75227871 | E28: 4070 | F28: =+E28/($E28+$G28+$I28) -> 0.20157496 | G28: 0 | H28: =+G28/($E28+$G28+$I28) -> 0 | I28: 16121 | J28: =+I28/($E28+$G28+$I28) -> 0.79842504 | K28: =Tax_Rate -> 0.21 | L28: =D28*(1+(E28/I28)*(1-Tax_Rate)+(G28/I28)) -> 0.90231914
B29: "Optimal" Capital Structure: | C29: =Ticker -> BBY | D29: =+L21 -> 0.75227871 | E29: =+F29*($E28+$G28+$I28) -> 4163.255 | F29: =+F21 -> 0.2061936 | G29: =+H29*($E28+$G28+$I28) -> 0 | H29: =+H21 -> 0 | I29: =+J29*($E28+$G28+$I28) -> 16027.745 | J29: =+J21 -> 0.7938064 | K29: =Tax_Rate -> 0.21 | L29: =D29*(1+(E29/I29)*(1-Tax_Rate)+(G29/I29)) -> 0.90664997
B31: Cost of Equity Based on Comparables, Current Capital Structure: | L31: =+Risk_Free_Rate+Equity_Risk_Premium*L28 -> 0.081070419
B32: Cost of Equity Based on Comparables, "Optimal" Capital Structure: | L32: =+Risk_Free_Rate+Equity_Risk_Premium*L29 -> 0.081257944
B33: Cost of Equity Based on Historical Beta: | L33: =+Risk_Free_Rate+Equity_Risk_Premium*D23 -> 0.102187
B35: WACC = Cost of Equity * % Equity + Cost of Debt * % Debt * (1 - Tax Rate) + Cost of Preferred Stock * % Preferred Stock
B37: WACC, Current Capital Structure: | L37: =+L31*J28+Cost_of_Debt*(1-Tax_Rate)*F28+Cost_of_Preferred*H28 -> 0.07141691
B38: WACC, Current Capital Structure and Historical Cost of Equity: | L38: =+L33*J28+Cost_of_Debt*(1-Tax_Rate)*F28+Cost_of_Preferred*H28 -> 0.088276917
B39: WACC, "Optimal" Capital Structure: | L39: =+L32*J29+Cost_of_Debt*(1-Tax_Rate)*F29+Cost_of_Preferred*H29 -> 0.071344579
B41: Average WACC Produced by All Methods: | L41: =AVERAGE(L37:L39) -> 0.077012802

Sheet Public-Comps
B2: Comparable Companies – U.S. Specialty & Multi-Category Retailers with FY25 Revenue Between $10 Billion and $300 Billion
B3: ($ USD in Millions Except Per Share Amounts in USD as Stated)
B5: Operating Statistics: | F5: Capitalization | U5: Projected | V5: Projected | AC5: Public-Comps Summary | AD5: =TEXT(Company_Name,"")&" - Range of Valuation Multiples / Premiums" -> Best Buy Co. - Range of Valuation Multiples / Premiums | AJ5: =TEXT(Company_Name,"")&" - Implied Per Share Value Range" -> Best Buy Co. - Implied Per Share Value Range
D6: Share | E6: Diluted | F6: Equity | I6: Preferred | J6: Other & | K6: Enterprise | L6: Revenue | O6: EBITDA | R6: Net Income | U6: Revenue | V6: EBITDA | W6: EBITDA Margin
B7: Company Name | C7: Ticker | D7: Price | E7: Shares | F7: Value | G7: Cash | H7: Debt | I7: Stock | J7: NCI | K7: Value | L7: LTM | M7: =EOMONTH("10/06/2025",12) -> 46203 | N7: =EOMONTH(M7,12) -> 46568 | O7: =$L$7 -> LTM | P7: =+$M$7 -> 46203 | Q7: =+$N$7 -> 46568 | R7: =$L$7 -> LTM | S7: =+$M$7 -> 46203 | T7: =+$N$7 -> 46568 | U7: Growth | V7: Growth | W7: =$L$7 -> LTM | X7: =+$M$7 -> 46203 | Y7: =+$N$7 -> 46568 | AE7: 75th | AG7: 25th | AI7: Applicable | AK7: 25th | AM7: 75th
B8: The Kroger Co. | C8: KR | D8: 65.9 | E8: 720 | F8: =+D8*E8 -> 47448 | G8: -3960 | H8: 25170 | I8: 0 | J8: 0 | K8: =+F8+G8+H8+I8+J8 -> 68658 | L8: 147123 | M8: 148681 | N8: 152794 | O8: 7920 | P8: 8110 | Q8: 8490 | R8: 2665 | S8: 2989 | T8: 3251 | U8: =IFERROR(+N8/M8-1,"N/A") -> 0.027663252 | V8: =IFERROR(+Q8/P8-1,"N/A") -> 0.046855734 | W8: =O8/L8 -> 0.053832507 | X8: =P8/M8 -> 0.054546311 | Y8: =Q8/N8 -> 0.055565009 | AD8: Maximum | AE8: Percentile | AF8: Median | AG8: Percentile | AH8: Minimum | AI8: Company | AJ8: Minimum | AK8: Percentile | AL8: Median | AM8: Percentile | AN8: Maximum
B9: Target Corporation | C9: TGT | D9: 85.63 | E9: 458 | F9: =+D9*E9 -> 39218.54 | G9: -4762 | H9: 19875 | I9: 0 | J9: 0 | K9: =+F9+G9+H9+I9+J9 -> 54331.54 | L9: 106566 | M9: 104953 | N9: 106882 | O9: 8653 | P9: 7883 | Q9: 8087 | R9: 4091 | S9: 3605 | T9: 3486 | U9: =IFERROR(+N9/M9-1,"N/A") -> 0.018379656 | V9: =IFERROR(+Q9/P9-1,"N/A") -> 0.025878473 | W9: =O9/L9 -> 0.081198506 | X9: =P9/M9 -> 0.075109811 | Y9: =Q9/N9 -> 0.075662881 | AD9: Multiple | AE9: Multiple | AF9: Multiple | AG9: Multiple | AH9: Multiple | AI9: Figure | AJ9: Multiple | AK9: Multiple | AL9: Multiple | AM9: Multiple | AN9: Multiple
B10: BJ’s Wholesale Club Holdings, Inc. | C10: BJ | D10: 90.86 | E10: 132.93 | F10: =+D10*E10 -> 12078.02 | G10: -28.272 | H10: 2843.916 | I10: 0 | J10: 0 | K10: =+F10+G10+H10+I10+J10 -> 14893.664 | L10: 20502 | M10: 21448 | N10: 22855 | O10: 1155 | P10: 1268 | Q10: 1334 | R10: 572.2 | S10: 622.2 | T10: 673.3 | U10: =IFERROR(+N10/M10-1,"N/A") -> 0.065600522 | V10: =IFERROR(+Q10/P10-1,"N/A") -> 0.052050473 | W10: =O10/L10 -> 0.056335967 | X10: =P10/M10 -> 0.059119731 | Y10: =Q10/N10 -> 0.058367972
B11: The TJX Companies, Inc. | C11: TJX | D11: 145.76 | E11: 1134.5 | F11: =+D11*E11 -> 165364.72 | G11: -5335 | H11: 12778 | I11: 0 | J11: 0 | K11: =+F11+G11+H11+I11+J11 -> 172807.72 | L11: 56360 | M11: 59940 | N11: 63321 | O11: 7406 | P11: 8076 | Q11: 8808 | R11: 4864 | S11: 5258 | T11: 5709 | U11: =IFERROR(+N11/M11-1,"N/A") -> 0.056406406 | V11: =IFERROR(+Q11/P11-1,"N/A") -> 0.09063893 | W11: =O11/L11 -> 0.13140525 | X11: =P11/M11 -> 0.13473473 | Y11: =Q11/N11 -> 0.13910077
B12: Costco Wholesale | C12: COST | D12: 885.98 | E12: 44.803 | F12: =+D12*E12 -> 39694.562 | G12: -15284 | H12: 8173 | I12: 0 | J12: 0 | K12: =+F12+G12+H12+I12+J12 -> 32583.562 | L12: 275235 | M12: 296834 | N12: 319063 | O12: 12809 | P12: 14231 | Q12: 15679 | R12: 8099 | S12: 8922 | T12: 9839 | U12: =IFERROR(+N12/M12-1,"N/A") -> 0.074886974 | V12: =IFERROR(+Q12/P12-1,"N/A") -> 0.1017497 | W12: =O12/L12 -> 0.046538413 | X12: =P12/M12 -> 0.047942621 | Y12: =Q12/N12 -> 0.049140765 | AC12: LTM TEV / Revenue: | AD12: {=TRANSPOSE(L33:T37)} -> 3.0661412 | AE12: 1.6771702 | AF12: 0.61814433 | AG12: 0.4774629 | AH12: 0.11838451 | AI12: {=TRANSPOSE(L21:T21)} -> 41528 | AJ12: =(AJ24+SUM($AF$23:$AF$29))/$AF$32 -> 10.683692 | AK12: =(AK24+SUM($AF$23:$AF$29))/$AF$32 -> 79.401696 | AL12: =(AL24+SUM($AF$23:$AF$29))/$AF$32 -> 106.32436 | AM12: =(AM24+SUM($AF$23:$AF$29))/$AF$32 -> 308.99361 | AN12: =(AN24+SUM($AF$23:$AF$29))/$AF$32 -> 574.80554
B13: Lowe's Companies, Inc. | C13: LOW | D13: 229.44 | E13: 561.957 | F13: =+D13*E13 -> 128935.41 | G13: -1761 | H13: 39678 | I13: 0 | J13: 0 | K13: =+F13+G13+H13+I13+J13 -> 166852.41 | L13: 83674 | M13: 85934 | N13: 92907 | O13: 12261 | P13: 12369 | Q13: 13231 | R13: 6957 | S13: 6777 | T13: 7415 | U13: =IFERROR(+N13/M13-1,"N/A") -> 0.081143668 | V13: =IFERROR(+Q13/P13-1,"N/A") -> 0.069690355 | W13: =O13/L13 -> 0.14653297 | X13: =P13/M13 -> 0.14393604 | Y13: =Q13/N13 -> 0.14241123 | AC13: ="CY "&TEXT(EOMONTH(Hist_Year,12),"AA")&" TEV / Revenue:" -> CY 26 TEV / Revenue: | AD13: 2.8830117 | AE13: 1.6298278 | AF13: 0.6060415 | AG13: 0.47575418 | AH13: 0.10977032 | AI13: 41797 | AJ13: =(AJ25+SUM($AF$23:$AF$29))/$AF$32 -> 9.1712391 | AK13: =(AK25+SUM($AF$23:$AF$29))/$AF$32 -> 79.664454 | AL13: =(AL25+SUM($AF$23:$AF$29))/$AF$32 -> 104.75947 | AM13: =(AM25+SUM($AF$23:$AF$29))/$AF$32 -> 301.95393 | AN13: =(AN25+SUM($AF$23:$AF$29))/$AF$32 -> 543.33331
AC14: ="CY "&TEXT(EOMONTH(Hist_Year,24),"AA")&" TEV / Revenue:" -> CY 27 TEV / Revenue: | AD14: 2.7290744 | AE14: 1.5098456 | AF14: 0.57999544 | AG14: 0.46409558 | AH14: 0.10212266 | AI14: 42451 | AJ14: =(AJ26+SUM($AF$23:$AF$29))/$AF$32 -> 8.0059815 | AK14: =(AK26+SUM($AF$23:$AF$29))/$AF$32 -> 78.817559 | AL14: =(AL26+SUM($AF$23:$AF$29))/$AF$32 -> 101.49067 | AM14: =(AM26+SUM($AF$23:$AF$29))/$AF$32 -> 283.39422 | AN14: =(AN26+SUM($AF$23:$AF$29))/$AF$32 -> 521.90796
B15: Maximum | D15: =MAX(D8:D13) -> 885.98 | F15: =MAX(F8:F13) -> 165364.72 | K15: =MAX(K8:K13) -> 172807.72 | L15: =MAX(L8:L13) -> 275235 | M15: =MAX(M8:M13) -> 296834 | N15: =MAX(N8:N13) -> 319063 | O15: =MAX(O8:O13) -> 12809 | P15: =MAX(P8:P13) -> 14231 | Q15: =MAX(Q8:Q13) -> 15679 | R15: =MAX(R8:R13) -> 8099 | ... Y15: =MAX(Y8:Y13) -> 0.14241123 | AC15: LTM TEV / EBITDA: | AD15: 23.333476 | AE15: 13.430026 | AF15: 10.781943 | AG15: 6.8764288 | AH15: 2.5438022 | AI15: 2621 | AJ15: =(AJ27+SUM($AF$23:$AF$29))/$AF$32 -> 18.75297 | AK15: =(AK27+SUM($AF$23:$AF$29))/$AF$32 -> 71.083912 | AL15: =(AL27+SUM($AF$23:$AF$29))/$AF$32 -> 118.25605 | AM15: =(AM27+SUM($AF$23:$AF$29))/$AF$32 -> 150.24049 | AN15: =(AN27+SUM($AF$23:$AF$29))/$AF$32 -> 269.85773
B16: 75th Percentile | D16: =QUARTILE(D8:D13,3) -> 208.52 | F16: =QUARTILE(F8:F13,3) -> 108563.56 | K16: =QUARTILE(K8:K13,3) -> 142303.81 | L16: =QUARTILE(L8:L13,3) -> 136983.75 | M16: =QUARTILE(M8:M13,3) -> 137749 | N16: =QUARTILE(N8:N13,3) -> 141316 | O16: =QUARTILE(O8:O13,3) -> 11359 | P16: =QUARTILE(P8:P13,3) -> 11304.25 | Q16: =QUARTILE(Q8:Q13,3) -> 12125.25 | R16: =QUARTILE(R8:R13,3) -> 6433.75 | ... Y16: =QUARTILE(Y8:Y13,3) -> 0.1232413 | AC16: ="CY "&TEXT(EOMONTH(Hist_Year,12),"AA")&" TEV / EBITDA:" -> CY 26 TEV / EBITDA: | AD16: 21.397687 | AE16: 13.053621 | AF16: 10.105818 | AG16: 7.2856423 | AH16: 2.2896186 | AI16: 2606 | AJ16: =(AJ28+SUM($AF$23:$AF$29))/$AF$32 -> 15.524585 | AK16: =(AK28+SUM($AF$23:$AF$29))/$AF$32 -> 75.522916 | AL16: =(AL28+SUM($AF$23:$AF$29))/$AF$32 -> 109.39102 | AM16: =(AM28+SUM($AF$23:$AF$29))/$AF$32 -> 144.79182 | AN16: =(AN28+SUM($AF$23:$AF$29))/$AF$32 -> 244.99752
B17: Median | D17: =MEDIAN(D8:D13) -> 118.31 | F17: =MEDIAN(F8:F13) -> 43571.281 | K17: =MEDIAN(K8:K13) -> 61494.77 | L17: =MEDIAN(L8:L13) -> 95120 | M17: =MEDIAN(M8:M13) -> 95443.5 | N17: =MEDIAN(N8:N13) -> 99894.5 | O17: =MEDIAN(O8:O13) -> 8286.5 | P17: =MEDIAN(P8:P13) -> 8093 | Q17: =MEDIAN(Q8:Q13) -> 8649 | R17: =MEDIAN(R8:R13) -> 4477.5 | ... Y17: =MEDIAN(Y8:Y13) -> 0.067015426 | AC17: ="CY "&TEXT(EOMONTH(Hist_Year,24),"AA")&" TEV / EBITDA:" -> CY 27 TEV / EBITDA: | AD17: 19.619405 | AE17: 12.249205 | AF17: 9.6257957 | AG17: 7.0605165 | AH17: 2.0781658 | AI17: 2692 | AJ17: =(AJ29+SUM($AF$23:$AF$29))/$AF$32 -> 13.808808 | AK17: =(AK29+SUM($AF$23:$AF$29))/$AF$32 -> 75.617509 | AL17: =(AL29+SUM($AF$23:$AF$29))/$AF$32 -> 107.44116 | AM17: =(AM29+SUM($AF$23:$AF$29))/$AF$32 -> 139.98594 | AN17: =(AN29+SUM($AF$23:$AF$29))/$AF$32 -> 231.41718
B18: 25th Percentile | D18: =QUARTILE(D8:D13,1) -> 86.9375 | F18: =QUARTILE(F8:F13,1) -> 39337.545 | K18: =QUARTILE(K8:K13,1) -> 38020.556 | L18: =QUARTILE(L8:L13,1) -> 63188.5 | M18: =QUARTILE(M8:M13,1) -> 66438.5 | N18: =QUARTILE(N8:N13,1) -> 70717.5 | O18: =QUARTILE(O8:O13,1) -> 7534.5 | P18: =QUARTILE(P8:P13,1) -> 7931.25 | Q18: =QUARTILE(Q8:Q13,1) -> 8187.75 | R18: =QUARTILE(R8:R13,1) -> 3021.5 | ... Y18: =QUARTILE(Y8:Y13,1) -> 0.05626575 | AC18: LTM P / E: | AD18: 33.997681 | AE18: 20.464327 | AF18: 18.16866 | AG18: 11.640938 | AH18: 4.9011683 | AI18: 927 | AJ18: =(AJ30+SUM($AF$23:$AF$29))/$AF$32 -> 8.9653088 | AK18: =(AK30+SUM($AF$23:$AF$29))/$AF$32 -> 37.756859 | AL18: =(AL30+SUM($AF$23:$AF$29))/$AF$32 -> 65.642564 | AM18: =(AM30+SUM($AF$23:$AF$29))/$AF$32 -> 75.449402 | AN18: =(AN30+SUM($AF$23:$AF$29))/$AF$32 -> 133.26239
B19: Minimum | D19: =MIN(D8:D13) -> 65.9 | F19: =MIN(F8:F13) -> 12078.02 | K19: =MIN(K8:K13) -> 14893.664 | L19: =MIN(L8:L13) -> 20502 | M19: =MIN(M8:M13) -> 21448 | N19: =MIN(N8:N13) -> 22855 | O19: =MIN(O8:O13) -> 1155 | P19: =MIN(P8:P13) -> 1268 | Q19: =MIN(Q8:Q13) -> 1334 | R19: =MIN(R8:R13) -> 572.2 | ... Y19: =MIN(Y8:Y13) -> 0.049140765 | AC19: ="CY "&TEXT(EOMONTH(Hist_Year,12),"AA")&" P / E:" -> CY 26 P / E: | AD19: 31.450118 | AE19: 19.315208 | AF19: 17.449823 | AG19: 12.127748 | AH19: 4.4490654 | AI19: 1204 | AJ19: =(AJ31+SUM($AF$23:$AF$29))/$AF$32 -> 12.713197 | AK19: =(AK31+SUM($AF$23:$AF$29))/$AF$32 -> 55.317502 | AL19: =(AL31+SUM($AF$23:$AF$29))/$AF$32 -> 84.846434 | AM19: =(AM31+SUM($AF$23:$AF$29))/$AF$32 -> 95.196309 | AN19: =(AN31+SUM($AF$23:$AF$29))/$AF$32 -> 162.52549
AC20: ="CY "&TEXT(EOMONTH(Hist_Year,24),"AA")&" P / E:" -> CY 27 P / E: | AD20: 28.965619 | AE20: 17.80102 | AF20: 15.991676 | AG20: 12.086447 | AH20: 4.0344102 | AI20: 1364 | AJ20: =(AJ32+SUM($AF$23:$AF$29))/$AF$32 -> 13.38721 | AK20: =(AK32+SUM($AF$23:$AF$29))/$AF$32 -> 64.000014 | AL20: =(AL32+SUM($AF$23:$AF$29))/$AF$32 -> 88.547165 | AM20: =(AM32+SUM($AF$23:$AF$29))/$AF$32 -> 99.920188 | AN20: =(AN32+SUM($AF$23:$AF$29))/$AF$32 -> 170.09767
B21: Best Buy Co. Inc. | C21: BBY | D21: 74.29 | E21: =Diluted_Shares -> 217 | F21: =+D21*E21 -> 16120.93 | G21: =-[2]ValSum!E23-[2]ValSum!E24-[2]ValSum!E25-[2]ValSum!E26 -> -1447 | H21: =-[2]ValSum!E27 -> 4070 | I21: =-[2]ValSum!E28 -> 0 | J21: =-[2]ValSum!E29-[2]ValSum!E30-[2]ValSum!E31-[2]ValSum!E32 -> 0 | K21: =+F21+G21+H21+I21+J21 -> 18743.93 | L21: 41528 | M21: 41797 | N21: 42451 | O21: 2621 | P21: 2606 | Q21: 2692 | R21: 927 | S21: 1204 | T21: 1364 | U21: =IFERROR(+N21/M21-1,"N/A") -> 0.015647056 | V21: =IFERROR(+Q21/P21-1,"N/A") -> 0.033000767 | W21: =O21/L21 -> 0.063114044 | X21: =P21/M21 -> 0.062348972 | Y21: =Q21/N21 -> 0.063414289
AC22: Implied Enterprise Value (Based on Median LTM EV/EBITDA): | AF22: =AL27 -> 28259.473 | AH22: Implied Enterprise Value or Equity Value at a Range of Multiples:
B23: Valuation Statistics: | F23: Capitalization | L23: Enterprise Value / | O23: Enterprise Value / | AC23: (+) Cash & Investments: | AF23: 1447
F24: Equity | K24: Enterprise | L24: Revenue | O24: EBITDA | R24: P / E Multiple | AC24: (+) Net Operating Losses: | AF24: 25.089 | AH24: Enterprise Value --> | AJ24: =AH12*$AI12 -> 4916.2721 | AK24: =AG12*$AI12 -> 19828.079 | AL24: =AF12*$AI12 -> 25670.298 | AM24: =AE12*$AI12 -> 69649.525 | AN24: =AD12*$AI12 -> 127330.71
B25: Company Name | F25: Value | K25: Value | L25: =$L$7 -> LTM | M25: =+$M$7 -> 46203 | N25: =+$N$7 -> 46568 | O25: =$L$7 -> LTM | P25: =+$M$7 -> 46203 | Q25: =+$N$7 -> 46568 | R25: =$L$7 -> LTM | S25: =+$M$7 -> 46203 | T25: =+$N$7 -> 46568 | AC25: (-) Debt & Finance Leases: | AF25: -4070 | AH25: Enterprise Value --> | AJ25: =AH13*$AI13 -> 4588.0699 | AK25: =AG13*$AI13 -> 19885.098 | AL25: =AF13*$AI13 -> 25330.717 | AM25: =AE13*$AI13 -> 68121.914 | AN25: =AD13*$AI13 -> 120501.24
B26: =+B8 -> The Kroger Co. | C26: =+C8 -> KR | F26: =+F8 -> 47448 | K26: =+K8 -> 68658 | L26: =IFERROR(IF(OR(+$K8/L8<0,+$K8/L8>=100),"NM",+$K8/L8),"N/A") -> 0.46667074 | M26: =IFERROR(IF(OR(+$K8/M8<0,+$K8/M8>=100),"NM",+$K8/M8),"N/A") -> 0.46178059 | N26: =IFERROR(IF(OR(+$K8/N8<0,+$K8/N8>=100),"NM",+$K8/N8),"N/A") -> 0.44935011 | O26: =IFERROR(IF(OR(+$K8/O8<0,+$K8/O8>=100),"NM",+$K8/O8),"N/A") -> 8.6689394 | P26: =IFERROR(IF(OR(+$K8/P8<0,+$K8/P8>=100),"NM",+$K8/P8),"N/A") -> 8.4658446 | Q26: =IFERROR(IF(OR(+$K8/Q8<0,+$K8/Q8>=100),"NM",+$K8/Q8),"N/A") -> 8.0869258 | R26: =IFERROR(IF(OR(+$F8/R8<0,+$F8/R8>=100),"NM",+$F8/R8),"N/A") -> 17.804128 | S26: =IFERROR(IF(OR(+$F8/S8<0,+$F8/S8>=100),"NM",+$F8/S8),"N/A") -> 15.874205 | T26: =IFERROR(IF(OR(+$F8/T8<0,+$F8/T8>=100),"NM",+$F8/T8),"N/A") -> 14.594894 | AC26: (-) Preferred Stock: | AF26: 0 | AH26: Enterprise Value --> | AJ26: =AH14*$AI14 -> 4335.209 | AK26: =AG14*$AI14 -> 19701.321 | AL26: =AF14*$AI14 -> 24621.386 | AM26: =AE14*$AI14 -> 64094.457 | AN26: =AD14*$AI14 -> 115851.94
B27: =+B9 -> Target Corporation | C27: =+C9 -> TGT | F27: =+F9 -> 39218.54 | K27: =+K9 -> 54331.54 | L27: =IFERROR(IF(OR(+$K9/L9<0,+$K9/L9>=100),"NM",+$K9/L9),"N/A") -> 0.50983935 | M27: =IFERROR(IF(OR(+$K9/M9<0,+$K9/M9>=100),"NM",+$K9/M9),"N/A") -> 0.51767496 | N27: =IFERROR(IF(OR(+$K9/N9<0,+$K9/N9>=100),"NM",+$K9/N9),"N/A") -> 0.50833199 | O27: =IFERROR(IF(OR(+$K9/O9<0,+$K9/O9>=100),"NM",+$K9/O9),"N/A") -> 6.2789252 | P27: =IFERROR(IF(OR(+$K9/P9<0,+$K9/P9>=100),"NM",+$K9/P9),"N/A") -> 6.8922415 | Q27: =IFERROR(IF(OR(+$K9/Q9<0,+$K9/Q9>=100),"NM",+$K9/Q9),"N/A") -> 6.7183801 | R27: =IFERROR(IF(OR(+$F9/R9<0,+$F9/R9>=100),"NM",+$F9/R9),"N/A") -> 9.5865412 | S27: =IFERROR(IF(OR(+$F9/S9<0,+$F9/S9>=100),"NM",+$F9/S9),"N/A") -> 10.878929 | T27: =IFERROR(IF(OR(+$F9/T9<0,+$F9/T9>=100),"NM",+$F9/T9),"N/A") -> 11.250298 | AC27: (-) Operating Leases: | AF27: 0 | AH27: Enterprise Value --> | AJ27: =AH15*$AI15 -> 6667.3055 | AK27: =AG15*$AI15 -> 18023.12 | AL27: =AF15*$AI15 -> 28259.473 | AM27: =AE15*$AI15 -> 35200.098 | AN27: =AD15*$AI15 -> 61157.039
B28: =+B10 -> BJ’s Wholesale Club Holdings, Inc. | C28: =+C10 -> BJ | F28: =+F10 -> 12078.02 | K28: =+K10 -> 14893.664 | L28: =IFERROR(IF(OR(+$K10/L10<0,+$K10/L10>=100),"NM",+$K10/L10),"N/A") -> 0.72644931 | M28: =IFERROR(IF(OR(+$K10/M10<0,+$K10/M10>=100),"NM",+$K10/M10),"N/A") -> 0.69440805 | N28: =IFERROR(IF(OR(+$K10/N10<0,+$K10/N10>=100),"NM",+$K10/N10),"N/A") -> 0.65165888 | O28: =IFERROR(IF(OR(+$K10/O10<0,+$K10/O10>=100),"NM",+$K10/O10),"N/A") -> 12.894947 | P28: =IFERROR(IF(OR(+$K10/P10<0,+$K10/P10>=100),"NM",+$K10/P10),"N/A") -> 11.745792 | Q28: =IFERROR(IF(OR(+$K10/Q10<0,+$K10/Q10>=100),"NM",+$K10/Q10),"N/A") -> 11.164666 | R28: =IFERROR(IF(OR(+$F10/R10<0,+$F10/R10>=100),"NM",+$F10/R10),"N/A") -> 21.108039 | S28: =IFERROR(IF(OR(+$F10/S10<0,+$F10/S10>=100),"NM",+$F10/S10),"N/A") -> 19.411797 | T28: =IFERROR(IF(OR(+$F10/T10<0,+$F10/T10>=100),"NM",+$F10/T10),"N/A") -> 17.938541 | AC28: (-) Noncontrolling Interests: | AF28: 0 | AH28: Enterprise Value --> | AJ28: =AH16*$AI16 -> 5966.746 | AK28: =AG16*$AI16 -> 18986.384 | AL28: =AF16*$AI16 -> 26335.762 | AM28: =AE16*$AI16 -> 34017.736 | AN28: =AD16*$AI16 -> 55762.372
B29: =+B11 -> The TJX Companies, Inc. | C29: =+C11 -> TJX | F29: =+F11 -> 165364.72 | K29: =+K11 -> 172807.72 | L29: =IFERROR(IF(OR(+$K11/L11<0,+$K11/L11>=100),"NM",+$K11/L11),"N/A") -> 3.0661412 | M29: =IFERROR(IF(OR(+$K11/M11<0,+$K11/M11>=100),"NM",+$K11/M11),"N/A") -> 2.8830117 | N29: =IFERROR(IF(OR(+$K11/N11<0,+$K11/N11>=100),"NM",+$K11/N11),"N/A") -> 2.7290744 | O29: =IFERROR(IF(OR(+$K11/O11<0,+$K11/O11>=100),"NM",+$K11/O11),"N/A") -> 23.333476 | P29: =IFERROR(IF(OR(+$K11/P11<0,+$K11/P11>=100),"NM",+$K11/P11),"N/A") -> 21.397687 | Q29: =IFERROR(IF(OR(+$K11/Q11<0,+$K11/Q11>=100),"NM",+$K11/Q11),"N/A") -> 19.619405 | R29: =IFERROR(IF(OR(+$F11/R11<0,+$F11/R11>=100),"NM",+$F11/R11),"N/A") -> 33.997681 | S29: =IFERROR(IF(OR(+$F11/S11<0,+$F11/S11>=100),"NM",+$F11/S11),"N/A") -> 31.450118 | T29: =IFERROR(IF(OR(+$F11/T11<0,+$F11/T11>=100),"NM",+$F11/T11),"N/A") -> 28.965619 | AC29: (-) Unfunded Pensions: | AF29: 0 | AH29: Enterprise Value --> | AJ29: =AH17*$AI17 -> 5594.4224 | AK29: =AG17*$AI17 -> 19006.911 | AL29: =AF17*$AI17 -> 25912.642 | AM29: =AE17*$AI17 -> 32974.86 | AN29: =AD17*$AI17 -> 52815.438
B30: =+B12 -> Costco Wholesale | C30: =+C12 -> COST | F30: =+F12 -> 39694.562 | K30: =+K12 -> 32583.562 | L30: =IFERROR(IF(OR(+$K12/L12<0,+$K12/L12>=100),"NM",+$K12/L12),"N/A") -> 0.11838451 | M30: =IFERROR(IF(OR(+$K12/M12<0,+$K12/M12>=100),"NM",+$K12/M12),"N/A") -> 0.10977032 | N30: =IFERROR(IF(OR(+$K12/N12<0,+$K12/N12>=100),"NM",+$K12/N12),"N/A") -> 0.10212266 | O30: =IFERROR(IF(OR(+$K12/O12<0,+$K12/O12>=100),"NM",+$K12/O12),"N/A") -> 2.5438022 | P30: =IFERROR(IF(OR(+$K12/P12<0,+$K12/P12>=100),"NM",+$K12/P12),"N/A") -> 2.2896186 | Q30: =IFERROR(IF(OR(+$K12/Q12<0,+$K12/Q12>=100),"NM",+$K12/Q12),"N/A") -> 2.0781658 | R30: =IFERROR(IF(OR(+$F12/R12<0,+$F12/R12>=100),"NM",+$F12/R12),"N/A") -> 4.9011683 | S30: =IFERROR(IF(OR(+$F12/S12<0,+$F12/S12>=100),"NM",+$F12/S12),"N/A") -> 4.4490654 | T30: =IFERROR(IF(OR(+$F12/T12<0,+$F12/T12>=100),"NM",+$F12/T12),"N/A") -> 4.0344102 | AC30: Implied Equity Value: | AF30: =SUM(AF22:AF29) -> 25661.562 | AH30: Equity Value --> | AJ30: =AH18*$AI18 -> 4543.383 | AK30: =AG18*$AI18 -> 10791.149 | AL30: =AF18*$AI18 -> 16842.347 | AM30: =AE18*$AI18 -> 18970.431 | AN30: =AD18*$AI18 -> 31515.85
B31: =+B13 -> Lowe's Companies, Inc. | C31: =+C13 -> LOW | F31: =+F13 -> 128935.41 | K31: =+K13 -> 166852.41 | L31: =IFERROR(IF(OR(+$K13/L13<0,+$K13/L13>=100),"NM",+$K13/L13),"N/A") -> 1.9940772 | M31: =IFERROR(IF(OR(+$K13/M13<0,+$K13/M13>=100),"NM",+$K13/M13),"N/A") -> 1.9416344 | N31: =IFERROR(IF(OR(+$K13/N13<0,+$K13/N13>=100),"NM",+$K13/N13),"N/A") -> 1.7959079 | O31: =IFERROR(IF(OR(+$K13/O13<0,+$K13/O13>=100),"NM",+$K13/O13),"N/A") -> 13.608385 | P31: =IFERROR(IF(OR(+$K13/P13<0,+$K13/P13>=100),"NM",+$K13/P13),"N/A") -> 13.489564 | Q31: =IFERROR(IF(OR(+$K13/Q13<0,+$K13/Q13>=100),"NM",+$K13/Q13),"N/A") -> 12.610718 | R31: =IFERROR(IF(OR(+$F13/R13<0,+$F13/R13>=100),"NM",+$F13/R13),"N/A") -> 18.533192 | S31: =IFERROR(IF(OR(+$F13/S13<0,+$F13/S13>=100),"NM",+$F13/S13),"N/A") -> 19.025441 | T31: =IFERROR(IF(OR(+$F13/T13<0,+$F13/T13>=100),"NM",+$F13/T13),"N/A") -> 17.388458 | AH31: Equity Value --> | AJ31: =AH19*$AI19 -> 5356.6748 | AK31: =AG19*$AI19 -> 14601.809 | AL31: =AF19*$AI19 -> 21009.587 | AM31: =AE19*$AI19 -> 23255.51 | AN31: =AD19*$AI19 -> 37865.942
AC32: Diluted Shares Outstanding: | AF32: 217 | AH32: Equity Value --> | AJ32: =AH20*$AI20 -> 5502.9355 | AK32: =AG20*$AI20 -> 16485.914 | AL32: =AF20*$AI20 -> 21812.646 | AM32: =AE20*$AI20 -> 24280.592 | AN32: =AD20*$AI20 -> 39509.105
B33: Maximum | F33: =MAX(F26:F31) -> 165364.72 | K33: =MAX(K26:K31) -> 172807.72 | L33: =MAX(L26:L31) -> 3.0661412 | M33: =MAX(M26:M31) -> 2.8830117 | N33: =MAX(N26:N31) -> 2.7290744 | O33: =MAX(O26:O31) -> 23.333476 | P33: =MAX(P26:P31) -> 21.397687 | Q33: =MAX(Q26:Q31) -> 19.619405 | R33: =MAX(R26:R31) -> 33.997681 | ... T33: =MAX(T26:T31) -> 28.965619
B34: 75th Percentile | F34: =QUARTILE(F26:F31,3) -> 108563.56 | K34: =QUARTILE(K26:K31,3) -> 142303.81 | L34: =QUARTILE(L26:L31,3) -> 1.6771702 | M34: =QUARTILE(M26:M31,3) -> 1.6298278 | N34: =QUARTILE(N26:N31,3) -> 1.5098456 | O34: =QUARTILE(O26:O31,3) -> 13.430026 | P34: =QUARTILE(P26:P31,3) -> 13.053621 | Q34: =QUARTILE(Q26:Q31,3) -> 12.249205 | R34: =QUARTILE(R26:R31,3) -> 20.464327 | ... T34: =QUARTILE(T26:T31,3) -> 17.80102 | AC34: Implied Share Price from Public-Comps: | AF34: =AF30/AF32 -> 118.25605
B35: Median | F35: =MEDIAN(F26:F31) -> 43571.281 | K35: =MEDIAN(K26:K31) -> 61494.77 | L35: =MEDIAN(L26:L31) -> 0.61814433 | M35: =MEDIAN(M26:M31) -> 0.6060415 | N35: =MEDIAN(N26:N31) -> 0.57999544 | O35: =MEDIAN(O26:O31) -> 10.781943 | P35: =MEDIAN(P26:P31) -> 10.105818 | Q35: =MEDIAN(Q26:Q31) -> 9.6257957 | R35: =MEDIAN(R26:R31) -> 18.16866 | ... T35: =MEDIAN(T26:T31) -> 15.991676 | AC35: Premium / (Discount) to Current: | AF35: =AF34/DCF!Share_Price -1 -> 0.59181649
B36: 25th Percentile | F36: =QUARTILE(F26:F31,1) -> 39337.545 | K36: =QUARTILE(K26:K31,1) -> 38020.556 | L36: =QUARTILE(L26:L31,1) -> 0.4774629 | M36: =QUARTILE(M26:M31,1) -> 0.47575418 | N36: =QUARTILE(N26:N31,1) -> 0.46409558 | O36: =QUARTILE(O26:O31,1) -> 6.8764288 | P36: =QUARTILE(P26:P31,1) -> 7.2856423 | Q36: =QUARTILE(Q26:Q31,1) -> 7.0605165 | R36: =QUARTILE(R26:R31,1) -> 11.640938 | ... T36: =QUARTILE(T26:T31,1) -> 12.086447
B37: Minimum | F37: =MIN(F26:F31) -> 12078.02 | K37: =MIN(K26:K31) -> 14893.664 | L37: =MIN(L26:L31) -> 0.11838451 | M37: =MIN(M26:M31) -> 0.10977032 | N37: =MIN(N26:N31) -> 0.10212266 | O37: =MIN(O26:O31) -> 2.5438022 | P37: =MIN(P26:P31) -> 2.2896186 | Q37: =MIN(Q26:Q31) -> 2.0781658 | R37: =MIN(R26:R31) -> 4.9011683 | ... T37: =MIN(T26:T31) -> 4.0344102
B39: =B21 -> Best Buy Co. Inc. | C39: =C21 -> BBY | F39: =+F21 -> 16120.93 | K39: =+K21 -> 18743.93 | L39: =IFERROR(IF(OR(+$K21/L21<0,+$K21/L21>=100),"NM",+$K21/L21),"N/A") -> 0.45135643 | M39: =IFERROR(IF(OR(+$K21/M21<0,+$K21/M21>=100),"NM",+$K21/M21),"N/A") -> 0.44845156 | N39: =IFERROR(IF(OR(+$K21/N21<0,+$K21/N21>=100),"NM",+$K21/N21),"N/A") -> 0.44154272 | O39: =IFERROR(IF(OR(+$K21/O21<0,+$K21/O21>=100),"NM",+$K21/O21),"N/A") -> 7.1514422 | P39: =IFERROR(IF(OR(+$K21/P21<0,+$K21/P21>=100),"NM",+$K21/P21),"N/A") -> 7.1926055 | Q39: =IFERROR(IF(OR(+$K21/Q21<0,+$K21/Q21>=100),"NM",+$K21/Q21),"N/A") -> 6.9628269 | R39: =IFERROR(IF(OR(+$F21/R21<0,+$F21/R21>=100),"NM",+$F21/R21),"N/A") -> 17.390431 | S39: =IFERROR(IF(OR(+$F21/S21<0,+$F21/S21>=100),"NM",+$F21/S21),"N/A") -> 13.389477 | T39: =IFERROR(IF(OR(+$F21/T21<0,+$F21/T21>=100),"NM",+$F21/T21),"N/A") -> 11.818864

Sheet MA_Comps
B2: Precedent Transactions - U.S.-Based Retail Companies with Transaction Enterprise Values Above $2.000 Million USD
B3: Announced Between November 2014 and November 2020
B4: ($ USD in Millions Except Per Share Amounts in USD as Stated)
B5: (Only >= 50% Acquisitions)
B7: =Company_Name&" - Comparable M&A Transactions:" -> Best Buy Co. - Comparable M&A Transactions: | I7: Valuation Multiples | N7: MA_Comps Summary | O7: =TEXT(Company_Name,"")&" - Range of Valuation Multiples / Premiums" -> Best Buy Co. - Range of Valuation Multiples / Premiums | U7: =TEXT(Company_Name,"")&" - Implied Per Share Value Range" -> Best Buy Co. - Implied Per Share Value Range
F8: Transaction | I8: TEV / | J8: TEV /
D9: Announcement | E9: Percentage | F9: Enterprise | G9: LTM | H9: LTM | I9: LTM | J9: LTM | P9: 75th | R9: 25th | T9: Applicable | V9: 25th | X9: 75th
B10: Acquirer Name | C10: Target Name | D10: Date | E10: Acquired | F10: Value | G10: Revenue | H10: EBITDA | I10: Revenue | J10: EBITDA | O10: Maximum | P10: Percentile | Q10: Median | R10: Percentile | S10: Minimum | T10: Company | U10: Minimum | V10: Percentile | W10: Median | X10: Percentile | Y10: Maximum
B11: Seven & Holdings | C11: Speedway LLC | D11: 44045 | E11: 1 | F11: 21000 | G11: 33000 | H11: 1500 | I11: =IFERROR(IF(OR(+$F11/G11<0,+$F11/G11>=100),"NM",+$F11/G11),"N/A") -> 0.63636364 | J11: =IFERROR(IF(OR(+$F11/H11<0,+$F11/H11>=100),"NM",+$F11/H11),"N/A") -> 14 | O11: Multiple | P11: Multiple | Q11: Multiple | R11: Multiple | S11: Multiple | T11: Figure | U11: Multiple | V11: Multiple | W11: Multiple | X11: Multiple | Y11: Multiple
B12: Home Depot Inc. | C12: HD Supply Holdings Inc. | D12: 44151 | E12: 1 | F12: 6100 | G12: 6590.8 | H12: 873 | I12: =IFERROR(IF(OR(+$F12/G12<0,+$F12/G12>=100),"NM",+$F12/G12),"N/A") -> 0.92553256 | J12: =IFERROR(IF(OR(+$F12/H12<0,+$F12/H12>=100),"NM",+$F12/H12),"N/A") -> 6.9873998
B13: Walmart Inc. | C13: Flipkart Private Ltd. | D13: 43229 | E13: 0.77 | F13: 16000 | G13: 4600 | H13: N/A | I13: =IFERROR(IF(OR(+$F13/G13<0,+$F13/G13>=100),"NM",+$F13/G13),"N/A") -> 3.4782609 | J13: =IFERROR(IF(OR(+$F13/H13<0,+$F13/H13>=100),"NM",+$F13/H13),"N/A") -> N/A | N13: LTM TEV / Revenue: | O13: {=TRANSPOSE(I25:J29)} -> 3.4782609 | P13: 1.0964286 | Q13: 0.87137033 | R13: 0.57205295 | S13: 0.14232271 | T13: ='Public-Comps'!L21 -> 41528 | U13: =(U18+SUM($Q$17:$Q$23))/$Q$26 -> 15.264822 | V13: =(V18+SUM($Q$17:$Q$23))/$Q$26 -> 97.503704 | W13: =(W18+SUM($Q$17:$Q$23))/$Q$26 -> 154.78505 | X13: =(X18+SUM($Q$17:$Q$23))/$Q$26 -> 197.85518 | Y13: =(Y18+SUM($Q$17:$Q$23))/$Q$26 -> 653.67422
B14: Amazon.com Inc. | C14: Whole Foods Market Inc. | D14: 42902 | E14: 1 | F14: 13700 | G14: 16000 | H14: 1400 | I14: =IFERROR(IF(OR(+$F14/G14<0,+$F14/G14>=100),"NM",+$F14/G14),"N/A") -> 0.85625 | J14: =IFERROR(IF(OR(+$F14/H14<0,+$F14/H14>=100),"NM",+$F14/H14),"N/A") -> 9.7857143 | N14: LTM TEV / EBITDA: | O14: 14 | P14: 9.7841498 | Q14: 8.8857143 | R14: 6.1530999 | S14: 3.125 | T14: ='Public-Comps'!O21 -> 2621 | U14: =(U19+SUM($Q$17:$Q$23))/$Q$26 -> 25.772876 | V14: =(V19+SUM($Q$17:$Q$23))/$Q$26 -> 62.347299 | W14: =(W19+SUM($Q$17:$Q$23))/$Q$26 -> 95.352747 | X14: =(X19+SUM($Q$17:$Q$23))/$Q$26 -> 106.20436 | Y14: =(Y19+SUM($Q$17:$Q$23))/$Q$26 -> 157.12483
B15: Walgreens Boots Alliance | C15: Rite Aid Corporation | D15: 42997 | E15: N/A | F15: 4375 | G15: 30740 | H15: 1400 | I15: =IFERROR(IF(OR(+$F15/G15<0,+$F15/G15>=100),"NM",+$F15/G15),"N/A") -> 0.14232271 | J15: =IFERROR(IF(OR(+$F15/H15<0,+$F15/H15>=100),"NM",+$F15/H15),"N/A") -> 3.125
B16: Walmart Inc. | C16: Jet.com Inc. | D16: 42590 | E16: 1 | F16: 3300 | G16: N/A | H16: N/A | I16: =IFERROR(IF(OR(+$F16/G16<0,+$F16/G16>=100),"NM",+$F16/G16),"N/A") -> N/A | J16: =IFERROR(IF(OR(+$F16/H16<0,+$F16/H16>=100),"NM",+$F16/H16),"N/A") -> N/A | N16: Implied Enterprise Value (Based on Median LTM EV/EBITDA): | Q16: =W19 -> 23289.457 | S16: Implied Enterprise Value or Equity Value at a Range of Multiples:
B17: Lowe's Companies Inc. | C17: RONA Inc. | D17: 42403 | E17: 1 | F17: 2400 | G17: 3060 | H17: 280 | I17: =IFERROR(IF(OR(+$F17/G17<0,+$F17/G17>=100),"NM",+$F17/G17),"N/A") -> 0.78431373 | J17: =IFERROR(IF(OR(+$F17/H17<0,+$F17/H17>=100),"NM",+$F17/H17),"N/A") -> 8.5714286 | N17: (+) Cash & Investments: | Q17: 1447
B18: CVC Cpaital Partners | C18: Petco Animal Supplies Inc. | D18: 42380 | E18: 1 | F18: 4600 | G18: 4200 | H18: 500 | I18: =IFERROR(IF(OR(+$F18/G18<0,+$F18/G18>=100),"NM",+$F18/G18),"N/A") -> 1.0952381 | J18: =IFERROR(IF(OR(+$F18/H18<0,+$F18/H18>=100),"NM",+$F18/H18),"N/A") -> 9.2 | N18: (+) Net Operating Losses: | Q18: 25.089 | S18: Enterprise Value --> | U18: =S13*$T13 -> 5910.3774 | V18: =R13*$T13 -> 23756.215 | W18: =Q13*$T13 -> 36186.267 | X18: =P13*$T13 -> 45532.486 | Y18: =O13*$T13 -> 144445.22
B19: BC Partners | C19: PetSmart Inc. | D19: 41945 | E19: 1 | F19: 8700 | G19: 6900 | H19: 889.62 | I19: =IFERROR(IF(OR(+$F19/G19<0,+$F19/G19>=100),"NM",+$F19/G19),"N/A") -> 1.2608696 | J19: =IFERROR(IF(OR(+$F19/H19<0,+$F19/H19>=100),"NM",+$F19/H19),"N/A") -> 9.7794564 | N19: (-) Debt & Finance Leases: | Q19: -4070 | S19: Enterprise Value --> | U19: =S14*$T14 -> 8190.625 | V19: =R14*$T14 -> 16127.275 | W19: =Q14*$T14 -> 23289.457 | X19: =P14*$T14 -> 25644.257 | Y19: =O14*$T14 -> 36694
B20: Dollar Tree Inc. | C20: Family Dollar Stores Inc. | D20: 42191 | E20: 1 | F20: 9200 | G20: 10378 | H20: 815 | I20: =IFERROR(IF(OR(+$F20/G20<0,+$F20/G20>=100),"NM",+$F20/G20),"N/A") -> 0.88649065 | J20: =IFERROR(IF(OR(+$F20/H20<0,+$F20/H20>=100),"NM",+$F20/H20),"N/A") -> 11.288344 | N20: (-) Preferred Stock: | Q20: 0
B21: Albertsons Companies | C21: Safeway Inc. | D21: 42034 | E21: 1 | F21: 9400 | G21: 36200 | H21: 1600 | I21: =IFERROR(IF(OR(+$F21/G21<0,+$F21/G21>=100),"NM",+$F21/G21),"N/A") -> 0.25966851 | J21: =IFERROR(IF(OR(+$F21/H21<0,+$F21/H21>=100),"NM",+$F21/H21),"N/A") -> 5.875 | N21: (-) Operating Leases: | Q21: 0
B22: Sycamore Partners | C22: Staples Inc. | D22: 42914 | E22: 1 | F22: 6900 | G22: 18200 | H22: 1400 | I22: =IFERROR(IF(OR(+$F22/G22<0,+$F22/G22>=100),"NM",+$F22/G22),"N/A") -> 0.37912088 | J22: =IFERROR(IF(OR(+$F22/H22<0,+$F22/H22>=100),"NM",+$F22/H22),"N/A") -> 4.9285714 | N22: (-) Noncontrolling Interests: | Q22: 0
B23: Target Corporation | C23: Shipt Inc. | D23: 43082 | E23: 1 | F23: 550 | G23: 500 | H23: N/A | I23: =IFERROR(IF(OR(+$F23/G23<0,+$F23/G23>=100),"NM",+$F23/G23),"N/A") -> 1.1 | J23: =IFERROR(IF(OR(+$F23/H23<0,+$F23/H23>=100),"NM",+$F23/H23),"N/A") -> N/A | N23: (-) Unfunded Pensions: | Q23: 0
N24: Implied Equity Value: | Q24: =SUM(Q16:Q23) -> 20691.546
C25: Maximum | F25: =MAX(F11:F23) -> 21000 | G25: =MAX(G11:G23) -> 36200 | H25: =MAX(H11:H23) -> 1600 | I25: =MAX(I11:I23) -> 3.4782609 | J25: =MAX(J11:J23) -> 14
C26: 75th Percentile | F26: =QUARTILE(F11:F23,3) -> 9400 | G26: =QUARTILE(G11:G23,3) -> 21335 | H26: =QUARTILE(H11:H23,3) -> 1400 | I26: =QUARTILE(I11:I23,3) -> 1.0964286 | J26: =QUARTILE(J11:J23,3) -> 9.7841498 | N26: Diluted Shares Outstanding: | Q26: 217
C27: Median | F27: =MEDIAN(F11:F23) -> 6900 | G27: =MEDIAN(G11:G23) -> 8639 | H27: =MEDIAN(H11:H23) -> 1144.81 | I27: =MEDIAN(I11:I23) -> 0.87137033 | J27: =MEDIAN(J11:J23) -> 8.8857143
C28: 25th Percentile | F28: =QUARTILE(F11:F23,1) -> 4375 | G28: =QUARTILE(G11:G23,1) -> 4500 | H28: =QUARTILE(H11:H23,1) -> 829.5 | I28: =QUARTILE(I11:I23,1) -> 0.57205295 | J28: =QUARTILE(J11:J23,1) -> 6.1530999 | N28: Implied Share Price from MA_Comps: | Q28: =Q24/Q26 -> 95.352747
C29: Minimum | F29: =MIN(F11:F23) -> 550 | G29: =MIN(G11:G23) -> 500 | H29: =MIN(H11:H23) -> 280 | I29: =MIN(I11:I23) -> 0.14232271 | J29: =MIN(J11:J23) -> 3.125 | N29: Premium / (Discount) to Current: | Q29: =Q28/DCF!Share_Price-1 -> 0.28352062
